<?xml version="1.0" ?>
<sdf version="1.8">
    <world name="car_world">
        <include>
            <uri>file:///home/deyung/ros2_ws/src/myproject/maze_model.sdf</uri>
            <pose>-10 -10 0 0 0 0</pose> <!-- Maze at origin -->
        </include>
        <physics name="1ms" type="ignored">
            <max_step_size>0.001</max_step_size>
            <real_time_factor>1.0</real_time_factor>
        </physics>
        <!-- Moving Forward-->
        <plugin 
            filename="gz-sim-triggered-publisher-system"
            name="gz::sim::systems::TriggeredPublisher">
            <input type="gz.msgs.Int32" topic="/keyboard/keypress">
            <match field="data">16777235</match>
            </input>
            <output type="gz.msgs.Twist" topic="/cmd_vel">
            linear: {x: 2}, angular: {z: 0.0}
            </output>
        </plugin>
        <!-- Moving Backward-->
        <plugin filename="gz-sim-triggered-publisher-system"
               name="gz::sim::systems::TriggeredPublisher">
           <input type="gz.msgs.Int32" topic="/keyboard/keypress">
               <match field="data">16777237</match>
           </input>
           <output type="gz.msgs.Twist" topic="/cmd_vel">
               linear: {x: -2}, angular: {z: 0.0}
           </output>
        </plugin>
        <!-- Left turn-->
         <plugin filename="gz-sim-triggered-publisher-system"
               name="gz::sim::systems::TriggeredPublisher">
           <input type="gz.msgs.Int32" topic="/keyboard/keypress">
               <match field="data">16777234</match>
           </input>
           <output type="gz.msgs.Twist" topic="/cmd_vel">
               linear: {x: 0.01}, angular: {z: 2}
           </output>
        </plugin>
        <!-- Right turn-->
         <plugin filename="gz-sim-triggered-publisher-system"
               name="gz::sim::systems::TriggeredPublisher">
           <input type="gz.msgs.Int32" topic="/keyboard/keypress">
               <match field="data">16777236</match>
           </input>
           <output type="gz.msgs.Twist" topic="/cmd_vel">
               linear: {x: 0.01}, angular: {z: -2}
           </output>
        </plugin>
        <plugin
            filename="gz-sim-sensors-system"
            name="gz::sim::systems::Sensors">
            <render_engine>ogre2</render_engine>
        </plugin>
        <plugin
            filename="gz-sim-physics-system"
            name="gz::sim::systems::Physics">
        </plugin>
        <plugin
            filename="gz-sim-user-commands-system"
            name="gz::sim::systems::UserCommands">
        </plugin>
        <plugin
            filename="gz-sim-scene-broadcaster-system"
            name="gz::sim::systems::SceneBroadcaster">
        </plugin>
        <plugin 
            filename="gz-sim-imu-system"
            name="gz::sim::systems::Imu">
        </plugin>
        <plugin 
            filename="gz-sim-contact-system"
            name="gz::sim::systems::Contact">
        </plugin>

        <light type="directional" name="sun">
            <cast_shadows>true</cast_shadows>
            <pose>0 0 10 0 0 0</pose>
            <diffuse>0.8 0.8 0.8 1</diffuse>
            <specular>0.2 0.2 0.2 1</specular>
            <attenuation>
                <range>1000</range>
                <constant>0.9</constant>
                <linear>0.01</linear>
                <quadratic>0.001</quadratic>
            </attenuation>
            <direction>-0.5 0.1 -0.9</direction>
        </light>

        <model name="ground_plane">
            <static>true</static>
            <link name="link">
                <collision name="collision">
                <geometry>
                    <plane>
                    <normal>0 0 1</normal>
                    </plane>
                </geometry>
                </collision>
                <visual name="visual">
                <geometry>
                    <plane>
                    <normal>0 0 1</normal>
                    <size>100 100</size>
                    </plane>
                </geometry>
                <material>
                    <ambient>0.8 0.8 0.8 1</ambient>
                    <diffuse>0.8 0.8 0.8 1</diffuse>
                    <specular>0.8 0.8 0.8 1</specular>
                </material>
                </visual>
            </link>
        </model>

        <model name='vehicle_blue' canonical_link='chassis'>

            <pose relative_to='world'>-8.9 -8.9 0.2 0 0 0</pose>   <!--the pose is relative to the start point of the maze-->
            <frame name="lidar_frame" attached_to='chassis'>
                    <pose>0.8 0 0.5 0 0 0</pose>
            </frame>
            <!--chassis-->
            <link name='chassis'>
                <pose relative_to='__model__'>0 0 0 0 0 0</pose>

                
                <inertial> <!--inertial properties of the link mass, inertia matix density is 1.14395
                all numbers is in SI unit-->
                    <mass>0.000143</mass>
                    <inertia>
                        <ixx>0.000000447</ixx>
                        <ixy>0</ixy>
                        <ixz>0</ixz>
                        <iyy>0.00000152</iyy>
                        <iyz>0</iyz>
                        <izz>0.00000179</izz>
                    </inertia>
                </inertial>
                <visual name='visual'>
                    <geometry>
                        <box>
                            <size>0.1 0.05 0.025</size>
                        </box>
                    </geometry>
                    <!--Color of the link -->
                    <material>
                        <ambient>0.0 0.0 1.0 1</ambient>
                        <diffuse>0.0 0.0 1.0 1</diffuse>
                        <specular>0.0 0.0 1.0 1</specular>
                    </material>
                </visual>
                <collision name='collision'>
                    <geometry>
                        <box>
                           <size>0.1 0.05 0.025</size>
                        </box>
                    </geometry>
                </collision>
                <sensor name="imu_sensor" type="imu">
                    <always_on>1</always_on>
                    <update_rate>1</update_rate>
                    <visualize>true</visualize>
                    <topic>imu</topic>
                </sensor>
                 
                <sensor name='gpu_lidar' type='gpu_lidar'>"
                    <pose relative_to='lidar_frame'>0 0 0 0 0 0</pose>
                    <topic>lidar</topic>
                    <update_rate>10</update_rate>
                    <ray>
                        <scan>
                            <horizontal>
                                <samples>640</samples>
                                <resolution>1</resolution>
                                <min_angle>-1.396263</min_angle>
                                <max_angle>1.396263</max_angle>
                            </horizontal>
                            <vertical>
                                <samples>1</samples>
                                <resolution>0.01</resolution>
                                <min_angle>0</min_angle>
                                <max_angle>0</max_angle>
                            </vertical>
                        </scan>
                        <range>
                            <min>0.08</min>
                            <max>10.0</max>
                            <resolution>0.01</resolution>
                        </range>
                    </ray>
                    <always_on>1</always_on>
                    <visualize>true</visualize>
                </sensor>
                <!-- Contact (bumper) sensor -->
                <sensor name="bumper_contacts" type="contact">
                      <update_rate>50</update_rate>
                      <!-- Monitor this/these collision(s) for contacts -->
                      <contact>
                        <collision>collision</collision>
                        <!-- You can repeat <collision>…</collision> for more parts -->
                      </contact>
                      <!-- Gazebo Transport topic name -->
                      <topic>contacts</topic>
                      <always_on>true</always_on>
                      <visualize>false</visualize>
                </sensor>
            </link>

            <!--Left wheel-->
            <link name='left_wheel'>
                <pose relative_to="chassis">-0.025 0.035 0 -1.5707 0 0</pose> <!--angles are in radian-->
                <inertial>
                    <mass>0.25</mass>
                    <inertia>
                        <ixx>0.000033333</ixx>
                        <ixy>0</ixy>
                        <ixz>0</ixz>
                        <iyy>0.000033333</iyy>
                        <iyz>0</iyz>
                        <izz>0.00005</izz>
                    </inertia>
                </inertial>
                <visual name='visual'>
                    <geometry>
                        <cylinder>
                            <radius>0.02</radius>
                            <length>0.02</length>
                        </cylinder>
                    </geometry>
                    <material>
                        <ambient>1.0 0.0 0.0 1</ambient>
                        <diffuse>1.0 0.0 0.0 1</diffuse>
                        <specular>1.0 0.0 0.0 1</specular>
                    </material>
                </visual>
                <collision name='collision'>
                    <geometry>
                        <cylinder>
                            <radius>0.02</radius>
                            <length>0.02</length>
                        </cylinder>
                    </geometry>
                </collision>
            </link>

            <!--The same as left wheel but with different position-->
            <link name='right_wheel'>
                <pose relative_to="chassis">-0.025 -0.035 0 -1.5707 0 0</pose> <!--angles are in radian-->
                <inertial>
                    <mass>0.25</mass>
                    <inertia>
                        <ixx>0.000033333</ixx>
                        <ixy>0</ixy>
                        <ixz>0</ixz>
                        <iyy>0.000033333</iyy>
                        <iyz>0</iyz>
                        <izz>0.00005</izz>
                    </inertia>
                </inertial>
                <visual name='visual'>
                    <geometry>
                        <cylinder>
                            <radius>0.02</radius>
                            <length>0.02</length>
                        </cylinder>
                    </geometry>
                    <material>
                        <ambient>1.0 0.0 0.0 1</ambient>
                        <diffuse>1.0 0.0 0.0 1</diffuse>
                        <specular>1.0 0.0 0.0 1</specular>
                    </material>
                </visual>
                <collision name='collision'>
                    <geometry>
                        <cylinder>
                            <radius>0.02</radius>
                            <length>0.02</length>
                        </cylinder>
                    </geometry>
                </collision>
            </link>

            <!--arbitrary frame-->
            <frame name="caster_frame" attached_to='chassis'>
                <pose>0.04 0 -0.01 0 0 0</pose>
            </frame>

            <!--caster wheel-->
            <link name='caster'>
                <pose relative_to='caster_frame'/>
                <inertial>
                    <mass>0.125</mass>
                    <inertia>
                        <ixx>0.000005</ixx>
                        <ixy>0</ixy>
                        <ixz>0</ixz>
                        <iyy>0.000005</iyy>
                        <iyz>0</iyz>
                        <izz>0.000005</izz>
                    </inertia>
                </inertial>
                <visual name='visual'>
                    <geometry>
                        <sphere>
                            <radius>0.01</radius>
                        </sphere>
                    </geometry>
                    <material>
                        <ambient>0.0 1 0.0 1</ambient>
                        <diffuse>0.0 1 0.0 1</diffuse>
                        <specular>0.0 1 0.0 1</specular>
                    </material>
                </visual>
                <collision name='collision'>
                    <geometry>
                        <sphere>
                            <radius>0.01</radius>
                        </sphere>
                    </geometry>
                </collision>
            </link>

            <!--left wheel joint-->
            <joint name='left_wheel_joint' type='revolute'>
                <pose relative_to='left_wheel'/>
                <parent>chassis</parent>
                <child>left_wheel</child>
                <axis>
                    <xyz expressed_in='__model__'>0 1 0</xyz> <!--can be descired to any frame or even arbitrary frames-->
                    <limit>
                        <lower>-1.79769e+308</lower>    <!--negative infinity-->
                        <upper>1.79769e+308</upper>     <!--positive infinity-->
                    </limit>
                </axis>
            </joint>

            <!--right wheel joint-->
            <joint name='right_wheel_joint' type='revolute'>
                <pose relative_to='right_wheel'/>
                <parent>chassis</parent>
                <child>right_wheel</child>
                <axis>
                    <xyz expressed_in='__model__'>0 1 0</xyz>
                    <limit>
                        <lower>-1.79769e+308</lower>    <!--negative infinity-->
                        <upper>1.79769e+308</upper>     <!--positive infinity-->
                    </limit>
                </axis>
            </joint>

            <!--caster wheel joint--> <!--pose defult value is the child-->
            <joint name='caster_wheel' type='ball'>
                <parent>chassis</parent>
                <child>caster</child>
            </joint>

            <plugin
                filename="gz-sim-diff-drive-system"
                name="gz::sim::systems::DiffDrive">
                <left_joint>left_wheel_joint</left_joint>
                <right_joint>right_wheel_joint</right_joint>
                <wheel_separation>1.2</wheel_separation>
                <wheel_radius>0.4</wheel_radius>
                <odom_publish_frequency>1</odom_publish_frequency>
                <topic>cmd_vel</topic>
                <odometry_topic>odom</odometry_topic>
            </plugin>       
        </model>
        



    </world>
</sdf>