<?xml version="1.0" ?>

<!-- =================================================================================== -->
<!-- |    This document was autogenerated by xacro from building_robot.urdf.xacro      | -->
<!-- |    EDITING THIS FILE BY HAND IS NOT RECOMMENDED                                 | -->
<!-- =================================================================================== -->
  <robot name="new_car" xmlns:xacro="http://ros.org/wiki/xacro">

  <xacro:include filename="inertia_macros.xacro"/>
  <xacro:include filename="ros2_control_ackerman.xacro"/>
  <!-- <xacro:include filename="gazebo_control.xacro"/> -->

  <!-- Colors -->

  <material name="White">
    <color rgba="1.0 1.0 1.0 1.0"/>
  </material>

  <material name="Blue">
      <color rgba="0.0 0.0 1.0 1.0"/>
  </material>

  <material name="Gray">
    <color rgba="0.5 0.5 0.5 1.0"/>
  </material>

  <material name="Black">
      <color rgba="0.1 0.1 0.1 1"/>
  </material>

  <material name="Cyan">
    <color rgba="0 1.0 1.0 1.0"/>
  </material>

  <!-- Dummy Root Link
  <link name="dummy_base_link"/>
  
  <joint name="dummy_base_joint" type="fixed">
    <parent link="dummy_base_link"/>
    <child link="base_link"/>
    <origin xyz="0 0 0" rpy="0 0 0"/>
  </joint> -->

  <!-- Robot Base -->
  <link name="base_link">
    <visual>
      <origin rpy="0 0 0" xyz="0 0 0"/>
      <geometry>
        <mesh filename="package://robot_description/description/meshes/new_car_chassis.stl" scale="0.58 0.58 0.58"/> 
      </geometry>
      <material name="Blue"/>
    </visual>
    <collision>
      <origin rpy="0 0 0" xyz="0 0 0"/>
      <geometry>
        <mesh filename="package://robot_description/description/meshes/new_car_chassis.stl" scale="0.58 0.58 0.58"/>
      </geometry>
    </collision>
    <xacro:inertia_box mass="113.4" x="1.65" y="0.92" z="1.13"> 
      <origin rpy="0 0 0" xyz="0 0 0"/>
    </xacro:inertia_box>
  </link>
  <!-- Robot Footprint -->
  <link name="base_footprint"/>
  <joint name="base_joint" type="fixed">
    <parent link="base_link"/>
    <child link="base_footprint"/>
    <origin rpy="0 0 0" xyz="0.0 0.0 -0.323"/>
  </joint>
  <!-- Front Wheels -->
  <link name="Front_Left_steering_link">
    <visual>
      <origin rpy="0 0 0" xyz="0 0 0"/>
      <geometry>
        <cylinder length="0.13" radius="0.01"/>
      </geometry>
      <material name="Black"/>
    </visual>
    <!-- added inertia -->
    <xacro:inertia_cylinder mass="0.001" length="0.13" radius="0.01"> 
      <origin rpy="0 0 0" xyz="0 0 0"/>
    </xacro:inertia_cylinder>
  </link>
  <joint name="Front_Left_steering_joint" type="revolute">
    <parent link="base_link"/>
    <child link="Front_Left_steering_link"/>
    <origin rpy="0 0 0" xyz="0.6 0.5800000000000001 -0.123"/>
    <axis xyz="0 0 1"/>
    <limit effort="1000.0" lower="-0.698" upper="0.698" velocity="0.5"/>
  </joint>
  <link name="Front_Left_wheel_link">
    <visual>
      <origin rpy="1.5707963267948966 0 0" xyz="0 0 0"/>
      <geometry>
        <cylinder length="0.13" radius="0.2"/>
      </geometry>
      <material name="Black"/>
    </visual>
    <collision>
      <origin rpy="1.5707963267948966 0 0" xyz="0 0 0"/>
      <geometry>
        <cylinder length="0.13" radius="0.2"/>
      </geometry>
    </collision>
    <xacro:inertia_cylinder mass="4.5" length="0.13" radius="0.2"> 
      <origin rpy="1.5707963267948966 0 0" xyz="0 0 0"/>
    </xacro:inertia_cylinder>
  </link>
  <joint name="Front_Left_wheel_joint" type="continuous">
    <parent link="Front_Left_steering_link"/>
    <child link="Front_Left_wheel_link"/>
    <origin rpy="0 0 0" xyz="0 0 0"/>
    <axis xyz="0 1 0"/>
  </joint>
  <link name="Front_Right_steering_link">
    <visual>
      <origin rpy="0 0 0" xyz="0 0 0"/>
      <geometry>
        <cylinder length="0.13" radius="0.01"/>
      </geometry>
      <material name="Black"/>
    </visual>
    <!-- added inertia -->
    <xacro:inertia_cylinder mass="0.001" length="0.13" radius="0.01"> 
      <origin rpy="0 0 0" xyz="0 0 0"/>
    </xacro:inertia_cylinder>
  </link>
  <joint name="Front_Right_steering_joint" type="revolute">
    <parent link="base_link"/>
    <child link="Front_Right_steering_link"/>
    <origin rpy="0 0 0" xyz="0.6 -0.5800000000000001 -0.123"/>
    <axis xyz="0 0 1"/>
    <limit effort="1000.0" lower="-0.698" upper="0.698" velocity="0.5"/>
  </joint>
  <link name="Front_Right_wheel_link">
    <visual>
      <origin rpy="1.5707963267948966 0 0" xyz="0 0 0"/>
      <geometry>
        <cylinder length="0.13" radius="0.2"/>
      </geometry>
      <material name="Black"/>
    </visual>
    <collision>
      <origin rpy="1.5707963267948966 0 0" xyz="0 0 0"/>
      <geometry>
        <cylinder length="0.13" radius="0.2"/>
      </geometry>
    </collision>
    <xacro:inertia_cylinder mass="4.5" length="0.13" radius="0.2"> 
      <origin rpy="1.5707963267948966 0 0" xyz="0 0 0"/>
    </xacro:inertia_cylinder>
  </link>
  <joint name="Front_Right_wheel_joint" type="continuous">
    <parent link="Front_Right_steering_link"/>
    <child link="Front_Right_wheel_link"/>
    <origin rpy="0 0 0" xyz="0 0 0"/>
    <axis xyz="0 1 0"/>
  </joint>
  <!-- Rear Wheels -->
  <link name="Rear_Left_link">
    <visual>
      <origin rpy="1.5707963267948966 0 0" xyz="0 0 0"/>
      <geometry>
        <cylinder length="0.17" radius="0.2"/>
      </geometry>
      <material name="Black"/>
    </visual>
    <collision>
      <origin rpy="1.5707963267948966 0 0" xyz="0 0 0"/>
      <geometry>
        <cylinder length="0.17" radius="0.2"/>
      </geometry>
    </collision>
    <xacro:inertia_cylinder mass="6.8" length="0.17" radius="0.2"> 
      <origin rpy="1.5707963267948966 0 0" xyz="0 0 0"/>
    </xacro:inertia_cylinder>
  </link>
  <joint name="Rear_Left_wheel_joint" type="continuous">
    <parent link="base_link"/>
    <child link="Rear_Left_link"/>
    <origin rpy="0 0 0" xyz="-0.45 0.61 -0.123"/>
    <axis xyz="0 1 0"/>
  </joint>
  <link name="Rear_Right_link">
    <visual>
      <origin rpy="1.5707963267948966 0 0" xyz="0 0 0"/>
      <geometry>
        <cylinder length="0.17" radius="0.2"/>
      </geometry>
      <material name="Black"/>
    </visual>
    <collision>
      <origin rpy="1.5707963267948966 0 0" xyz="0 0 0"/>
      <geometry>
        <cylinder length="0.17" radius="0.2"/>
      </geometry>
    </collision>
    <xacro:inertia_cylinder mass="6.8" length="0.17" radius="0.2"> 
      <origin rpy="1.5707963267948966 0 0" xyz="0 0 0"/>
    </xacro:inertia_cylinder>
  </link>
  <joint name="Rear_Right_wheel_joint" type="continuous">
    <parent link="base_link"/>
    <child link="Rear_Right_link"/>
    <origin rpy="0 0 0" xyz="-0.45 -0.61 -0.123"/>
    <axis xyz="0 1 0"/>
  </joint>
  <!-- Lidar -->
  <link name="velodyne">
    <visual>
      <origin rpy="0 0 0" xyz="0 0 0"/>
      <geometry>
        <cylinder length=".0762" radius=".0762"/>
      </geometry>
      <material name="Cyan"/>
    </visual>
    <collision>
      <origin rpy="0 0 0" xyz="0 0 0"/>
      <geometry>
        <cylinder length=".0762" radius=".0762"/>
      </geometry>
    </collision>
    <xacro:inertia_cylinder mass="1.36" length=".0762" radius=".0762"> 
      <origin rpy="0 0 0" xyz="0 0 0"/>
    </xacro:inertia_cylinder>
  </link>
  <joint name="velodyne_joint" type="fixed">
    <parent link="base_link"/>
    <child link="velodyne"/>
    <origin rpy="0 0 0" xyz="0 0 1.0414"/>
  </joint>
  <!-- Test box
  <link name="test">
    <visual>
      <origin rpy="0 0 0" xyz="0 0 0"/>
      <geometry>
        <box size="1.65 0.92 1.13"/>
      </geometry>
      <material name="Cyan"/>
    </visual>
    <collision>
      <origin rpy="0 0 0" xyz="0 0 0"/>
      <geometry>
        <box size="1.65 0.92 1.13"/>
      </geometry>
    </collision>
    <xacro:inertia_box mass="1.36" x="1.65" y="0.92" z="1.13"> 
      <origin rpy="0 0 0" xyz="0 0 0"/>
    </xacro:inertia_box>
  </link>
  <joint name="test_joint" type="fixed">
    <parent link="base_link"/>
    <child link="test"/>
    <origin rpy="0 0 0" xyz="0 0 .43"/>
  </joint> -->

</robot>
