<?xml version="1.0"?>
<robot name="ackermann_drive" xmlns:xacro="http://ros.org/wiki/xacro">

    <xacro:property name="base_width" value="1.041"/>
    <xacro:property name="base_length" value="1.892"/>
    <xacro:property name="base_height" value="0.626"/>

    <xacro:property name="front_wheel_radius" value="0.2"/>
    <xacro:property name="front_wheel_width" value="0.13"/>
    <xacro:property name="rear_wheel_radius" value="0.2"/>   
    <xacro:property name="rear_wheel_width" value="0.17"/>

    <xacro:include filename="inertia_macros.xacro"/>

    <!-- Colors -->
    <material name="White">
        <color rgba="1.0 1.0 1.0 1.0"/>
    </material>
    <material name="Blue">
        <color rgba="0.0 0.0 1.0 1.0"/>
    </material>
    <material name="Gray">
        <color rgba="0.5 0.5 0.5 1.0"/>
    </material>
    <material name="Black">
        <color rgba="0.1 0.1 0.1 1"/>
    </material>
    <material name="Cyan">
        <color rgba="0 1.0 1.0 1.0"/>
    </material>
    <material name="Red">
        <color rgba="1 0 0 1.0"/>
    </material>


    <link name="base_link" />

    <!-- Chassis -->
    <link name="chassis">
       

        <visual>
        <origin xyz="0 -0.01 0" rpy="0 0 0" />
            <geometry>
                <mesh filename="package://robot_description/description/meshes/new_car_chassis.stl" scale="0.58 0.5 0.58"/>
            </geometry>
            <material name="Blue"/>
        </visual>

        <collision>
            <!-- <origin xyz="0 -0.01 0" rpy="0 0 0" />
                <geometry>
                    <mesh filename="package://robot_description/description/meshes/new_car_chassis.stl" scale="0.58 0.58 0.58"/>
                </geometry> -->
        </collision>
        <!-- make box slightly smaller than actual to prevent accidental self collision y=0.92-->
        <xacro:inertia_box mass="150" x="1.65" y="0.92" z="1.13"> 
            <origin rpy="0 -0.01 0" xyz="0 0 0"/>
        </xacro:inertia_box>
    </link>

    <joint name="chassis_joint" type="fixed">
        <origin xyz="0 0 0.2" rpy="0 0 0" />
        <parent link="base_link" />
        <child link="chassis" />
    </joint>

    <!-- rear left wheel Link -->
    <link name="rear_left_wheel">
        <visual>
            <geometry>
                <cylinder radius="${rear_wheel_radius}" length="${rear_wheel_width}"/>
            </geometry>
            <material name="Black"/>
        </visual>
        <collision>
            <geometry>
                <cylinder radius="${rear_wheel_radius}" length="${rear_wheel_width}"/>
            </geometry>
        </collision>
        <xacro:inertia_cylinder mass="6.8" length="0.17" radius="0.2"> 
            <origin xyz="-0.6 0.42 0" rpy="-1.57 0 0"/>
        </xacro:inertia_cylinder>
    </link>

    <joint name="rear_left_wheel_joint" type="continuous">
        <origin xyz="-0.6 0.42 0" rpy="-1.57 0 0"/>
        <parent link="chassis" />
        <child link="rear_left_wheel" />
        <axis xyz="0 0 1" />
        <dynamics damping="0.2" />
    </joint>

    <!-- rear right wheel Link -->
    <link name="rear_right_wheel">
        <visual>
            <geometry>
                <cylinder radius="${rear_wheel_radius}" length="${rear_wheel_width}"/>
            </geometry>
            <material name="Black"/>
        </visual>
        <collision>
            <geometry>
                <cylinder radius="${rear_wheel_radius}" length="${rear_wheel_width}"/>
            </geometry>
        </collision>
        <xacro:inertia_cylinder mass="6.8" length="0.17" radius="0.2"> 
            <origin xyz="-0.6 -0.42 0" rpy="-1.57 0 0" />
        </xacro:inertia_cylinder>
    </link>

    <joint name="rear_right_wheel_joint" type="continuous">
        <origin xyz="-0.6 -0.42 0" rpy="-1.57 0 0" />
        <parent link="chassis" />
        <child link="rear_right_wheel" />
        <axis xyz="0 0 1" />
        <dynamics damping="0.2" />
    </joint>

    <!-- left steer Link -->
    <link name="left_wheel_steering">
        <inertial>
            <mass value="0.1"/>
            <inertia ixx="0" ixy="0.0" ixz="0.0" iyy="0.0" iyz="0.0" izz="0.0" />
        </inertial>
    </link>

    <joint name="left_wheel_steering_joint" type="revolute">
        <origin xyz="0.6 0.45 0" rpy="1.57 0 0"/>
        <parent link="chassis"/>
        <child link="left_wheel_steering"/>
        <axis xyz="0 1 0"/>
        <dynamics damping="0.2"/>
        <!-- effort = torque (N/m) Lower/upper = steering angle rad-->
        <limit effort="100.0" lower="-0.785" upper="0.785" velocity="30"/>
    </joint>

    <!-- right steer Link -->
    <link name="right_wheel_steering">
        <inertial>
            <mass value="0.1"/>
            <inertia ixx="0" ixy="0.0" ixz="0.0" iyy="0.0" iyz="0.0" izz="0.0" />
        </inertial>
    </link>

    <joint name="right_wheel_steering_joint" type="revolute">
        <origin xyz="0.6 -0.45 0" rpy="1.57 0 0"/>
        <parent link="chassis"/>
        <child link="right_wheel_steering"/>
        <axis xyz="0 1 0"/>
        <dynamics damping="0.2"/>
        <!-- effort = torque (N/m) Lower/upper = steering angle rad-->
        <limit effort="100.0" lower="-0.785" upper="0.785" velocity="30"/>
    </joint>

    <!-- front left wheel Link -->
    <link name="front_left_wheel">
         <visual>
            <geometry>
                <cylinder radius="${front_wheel_radius}" length="${front_wheel_width}"/>
            </geometry>
            <material name="Black"/>
        </visual>
        <collision>
            <geometry>
                <cylinder radius="${front_wheel_radius}" length="${front_wheel_width}"/>
            </geometry>
        </collision>
        <xacro:inertia_cylinder mass="4.5" length="0.13" radius="0.2"> 
            <origin xyz="0.6 0.45 0" rpy="1.57 0 0"/>
        </xacro:inertia_cylinder>
    </link>

    <joint name="front_left_wheel_joint" type="continuous">
        <origin xyz="0 0 0" rpy="0 0 0" />
        <parent link="left_wheel_steering" />
        <child link="front_left_wheel" />
        <axis xyz="0 0 1" />
        <dynamics damping="0.2" />
    </joint>

    <!-- front right wheel Link -->
    <link name="front_right_wheel">
        <visual>
            <geometry>
                <cylinder radius="${front_wheel_radius}" length="${front_wheel_width}"/>
            </geometry>
            <material name="Black"/>
        </visual>
        <collision>
            <geometry>
                <cylinder radius="${front_wheel_radius}" length="${front_wheel_width}"/>
            </geometry>
        </collision>
        <xacro:inertia_cylinder mass="4.5" length="0.13" radius="0.2"> 
            <origin xyz="0.6 -0.45 0" rpy="1.57 0 0"/>
        </xacro:inertia_cylinder>
    </link>

    <joint name="front_right_wheel_joint" type="continuous">
        <origin xyz="0 0 0" rpy="0 0 0" />
        <parent link="right_wheel_steering" />
        <child link="front_right_wheel" />
        <axis xyz="0 0 1" />
        <dynamics damping="0.2" />
    </joint>

    <!-- IMU -->
    <joint name="imu_joint" type="fixed">
        <origin xyz="0 0 0" rpy="0 0 0" />
        <parent link="chassis" />
        <child link="imu_link" />
    </joint>
    <link name="imu_link">
        <pose>0 0 0 0 0 0</pose>  <!-- Adjust height based on your vehicle -->
        <visual>
            <geometry>
                <box size ="0.05 0.05 0.01"/>
            </geometry>
            <material name ="White"/>
        </visual>
    </link>
</robot>